Workbook

Sheet Sign-off
A1: ReconDesk - Daily Custody Reconciliation Control
A2: Business date (as of): 2026-10-23
A3: Explanations generated by: rules only (AI disabled with --no-ai)
A4: Synthetic data for portfolio demonstration. Figures below are live formulas.
A6: Headline | B6: Cash | C6: Stock
A7: Items reconciled | B7: =COUNTA('Cash Recon'!$H$2:$H$200) -> 199 | C7: =COUNTA('Stock Recon'!$H$2:$H$46) -> 45
A8: Matched (incl. within tolerance) | B8: =COUNTIF('Cash Recon'!$H$2:$H$200,"MATCHED")+COUNTIF('Cash Recon'!$H$2:$H$200,"MATCHED_WITHIN_TOLERANCE") -> 173 | C8: =COUNTIF('Stock Recon'!$H$2:$H$46,"MATCHED") -> 36
A9: Breaks | B9: =B7-B8 -> 26 | C9: =C7-C8 -> 9
A10: Match rate | B10: =IF(B7=0,0,B8/B7) -> 0.86934673 | C10: =IF(C7=0,0,C8/C7) -> 0.8
A11: Break value (INR eq., absolute) | B11: =SUMPRODUCT((Breaks!$B$2:$B$36="CASH")*ABS(Breaks!$K$2:$K$36)) -> 6.2349554e+08 | C11: =SUMPRODUCT((Breaks!$B$2:$B$36="STOCK")*ABS(Breaks!$K$2:$K$36)) -> 6.0422818e+08
A12: HIGH priority breaks | B12: =COUNTIFS(Breaks!$B$2:$B$36,"CASH",Breaks!$P$2:$P$36,"HIGH") -> 15 | C12: =COUNTIFS(Breaks!$B$2:$B$36,"STOCK",Breaks!$P$2:$P$36,"HIGH") -> 6
A14: Cash breaks by type | B14: Count | C14: Value (INR eq.)
A15: AMOUNT_DIFF | B15: =COUNTIFS(Breaks!$B$2:$B$36,"CASH",Breaks!$G$2:$G$36,"AMOUNT_DIFF") -> 6 | C15: =SUMPRODUCT((Breaks!$B$2:$B$36="CASH")*(Breaks!$G$2:$G$36="AMOUNT_DIFF")*ABS(Breaks!$K$2:$K$36)) -> 1292702.4
A16: TIMING_DIFF | B16: =COUNTIFS(Breaks!$B$2:$B$36,"CASH",Breaks!$G$2:$G$36,"TIMING_DIFF") -> 8 | C16: =SUMPRODUCT((Breaks!$B$2:$B$36="CASH")*(Breaks!$G$2:$G$36="TIMING_DIFF")*ABS(Breaks!$K$2:$K$36)) -> 4.8878765e+08
A17: MISSING_AT_CUSTODIAN | B17: =COUNTIFS(Breaks!$B$2:$B$36,"CASH",Breaks!$G$2:$G$36,"MISSING_AT_CUSTODIAN") -> 5 | C17: =SUMPRODUCT((Breaks!$B$2:$B$36="CASH")*(Breaks!$G$2:$G$36="MISSING_AT_CUSTODIAN")*ABS(Breaks!$K$2:$K$36)) -> 1.2388068e+08
A18: MISSING_IN_BOOKS | B18: =COUNTIFS(Breaks!$B$2:$B$36,"CASH",Breaks!$G$2:$G$36,"MISSING_IN_BOOKS") -> 4 | C18: =SUMPRODUCT((Breaks!$B$2:$B$36="CASH")*(Breaks!$G$2:$G$36="MISSING_IN_BOOKS")*ABS(Breaks!$K$2:$K$36)) -> 5920548.2
A19: DUPLICATE_IN_BOOKS | B19: =COUNTIFS(Breaks!$B$2:$B$36,"CASH",Breaks!$G$2:$G$36,"DUPLICATE_IN_BOOKS") -> 2 | C19: =SUMPRODUCT((Breaks!$B$2:$B$36="CASH")*(Breaks!$G$2:$G$36="DUPLICATE_IN_BOOKS")*ABS(Breaks!$K$2:$K$36)) -> 725627.74
A20: DUPLICATE_AT_CUSTODIAN | B20: =COUNTIFS(Breaks!$B$2:$B$36,"CASH",Breaks!$G$2:$G$36,"DUPLICATE_AT_CUSTODIAN") -> 1 | C20: =SUMPRODUCT((Breaks!$B$2:$B$36="CASH")*(Breaks!$G$2:$G$36="DUPLICATE_AT_CUSTODIAN")*ABS(Breaks!$K$2:$K$36)) -> 2888328.4
A22: Stock breaks by type | B22: Count | C22: Value (INR eq.)
A23: QTY_BREAK | B23: =COUNTIFS(Breaks!$B$2:$B$36,"STOCK",Breaks!$G$2:$G$36,"QTY_BREAK") -> 5 | C23: =SUMPRODUCT((Breaks!$B$2:$B$36="STOCK")*(Breaks!$G$2:$G$36="QTY_BREAK")*ABS(Breaks!$K$2:$K$36)) -> 1.5876907e+08
A24: MISSING_AT_CUSTODIAN | B24: =COUNTIFS(Breaks!$B$2:$B$36,"STOCK",Breaks!$G$2:$G$36,"MISSING_AT_CUSTODIAN") -> 2 | C24: =SUMPRODUCT((Breaks!$B$2:$B$36="STOCK")*(Breaks!$G$2:$G$36="MISSING_AT_CUSTODIAN")*ABS(Breaks!$K$2:$K$36)) -> 271955265
A25: MISSING_IN_BOOKS | B25: =COUNTIFS(Breaks!$B$2:$B$36,"STOCK",Breaks!$G$2:$G$36,"MISSING_IN_BOOKS") -> 2 | C25: =SUMPRODUCT((Breaks!$B$2:$B$36="STOCK")*(Breaks!$G$2:$G$36="MISSING_IN_BOOKS")*ABS(Breaks!$K$2:$K$36)) -> 173503845
A27: Sign-off checklist | B27: Result
A28: Cash reconciliation completed | B28: =IF(B7>0,"YES","NO") -> YES
A29: Stock reconciliation completed | B29: =IF(C7>0,"YES","NO") -> YES
A30: Every HIGH break has an owner | B30: =IF(COUNTIFS(Breaks!$P$2:$P$36,"HIGH",Breaks!$T$2:$T$36,"")=0,"YES","NO") -> NO
A31: No break aged 8+ days | B31: =IF(COUNTIF(Breaks!$O$2:$O$36,"8+ days")=0,"YES","NO") -> YES
A32: Breaks still OPEN (not yet worked) | B32: =COUNTIF(Breaks!$U$2:$U$36,"OPEN") -> 35
A33: Breaks ESCALATED | B33: =COUNTIF(Breaks!$U$2:$U$36,"ESCALATED") -> 0
A34: Breaks RESOLVED today | B34: =COUNTIF(Breaks!$U$2:$U$36,"RESOLVED") -> 0
A36: Prepared by
A37: Reviewed by
A38: Sign-off time
A40: Yellow cells (here and on the Breaks sheet) are for the analyst to fill in.

Sheet Breaks
A1: Break ID | B1: Recon | C1: Account | D1: Reference / Position | E1: Txn Type / Security | F1: Ccy | G1: Break Type | H1: Books | I1: Custodian | J1: Difference | K1: Difference (INR eq.) | L1: Books Date | M1: Custodian Date | N1: Age (days) | O1: Age Bucket | P1: Priority | Q1: Probable Cause | R1: Explanation | S1: Next Action | T1: Owner | U1: Resolution Status | V1: Comments
A2: BRK-0001 | B2: CASH | C2: ACC-1001 | D2: CSH214576 | E2: TRADE_SETTLEMENT | F2: USD | G2: TIMING_DIFF | H2: 4068258 | I2: 4068258 | J2: 4068258 | K2: 3.4173367e+08 | L2: 2026-10-16 | M2: 2026-10-19 | N2: 7 | O2: 4-7 days | P2: HIGH | Q2: SETTLEMENT_LAG | R2: Same transaction, custodian value date is later than books. Usually a settlement delay. | S2: Confirm the actual settlement date with the custodian; expected to auto-clear. Escalate if it stays open past T+3. | U2: OPEN
A3: BRK-0002 | B3: STOCK | C3: ACC-1001 | D3: ACC-1001|US9Z01S10017 | E3: US9Z01S10017 Harbor Tech Inc | F3: USD | G3: MISSING_AT_CUSTODIAN | H3: 16650 | J3: -16650 | K3: -255104640 | L3: 2026-10-23 | M3: 2026-10-23 | N3: 0 | O3: 0-1 days | P3: HIGH | Q3: POSITION_NOT_AT_CUSTODIAN | R3: Books show a holding the custodian does not hold. | S3: Check whether the purchase settled and whether the securities were delivered to the right account. | U3: OPEN
A4: BRK-0003 | B4: STOCK | C4: ACC-1005 | D4: ACC-1005|US9Z01S10017 | E4: US9Z01S10017 Harbor Tech Inc | F4: USD | G4: MISSING_IN_BOOKS | I4: 11200 | J4: 11200 | K4: 171601920 | L4: 2026-10-23 | M4: 2026-10-23 | N4: 0 | O4: 0-1 days | P4: HIGH | Q4: UNBOOKED_POSITION | R4: Custodian holds a position that is not in the books. | S4: Find the trade or transfer behind it and book it, or ask the custodian to correct the account. | U4: OPEN
A5: BRK-0004 | B5: CASH | C5: ACC-1004 | D5: CSH246991 | E5: TRADE_SETTLEMENT | F5: USD | G5: TIMING_DIFF | H5: -1644453.5 | I5: -1644453.5 | J5: -1644453.5 | K5: -1.3813409e+08 | L5: 2026-10-16 | M5: 2026-10-17 | N5: 7 | O5: 4-7 days | P5: HIGH | Q5: SETTLEMENT_LAG | R5: Same transaction, custodian value date is later than books. Usually a settlement delay. | S5: Confirm the actual settlement date with the custodian; expected to auto-clear. Escalate if it stays open past T+3. | U5: OPEN
A6: BRK-0005 | B6: CASH | C6: ACC-1002 | D6: CSH864491 | E6: TRADE_SETTLEMENT | F6: USD | G6: MISSING_AT_CUSTODIAN | H6: -1396909.1 | J6: -1396909.1 | K6: -1.1734036e+08 | L6: 2026-10-21 | N6: 2 | O6: 2-3 days | P6: HIGH | Q6: POSSIBLE_FAILED_SETTLEMENT | R6: Trade settlement is in the books but no cash moved at the custodian. The trade may have failed or is pending. | S6: Check settlement status with the custodian / counterparty; if failed, update books and inform the client. | U6: OPEN
A7: BRK-0006 | B7: STOCK | C7: ACC-1005 | D7: ACC-1005|US9Z02S10015 | E7: US9Z02S10015 Summit Health Corp | F7: USD | G7: QTY_BREAK | H7: 26100 | I7: 39150 | J7: 13050 | K7: 82105380 | L7: 2026-10-23 | M7: 2026-10-23 | N7: 0 | O7: 0-1 days | P7: HIGH | Q7: UNBOOKED_CORPORATE_ACTION | R7: Custodian processed a corporate action that the books have not captured. | S7: Check the corporate action announcement and entitlement, then book the event. | U7: OPEN
A8: BRK-0007 | B8: STOCK | C8: ACC-1002 | D8: ACC-1002|INE108S01015 | E8: INE108S01015 Kaveri Finance Ltd | F8: INR | G8: QTY_BREAK | H8: 49500 | I8: 99000 | J8: 49500 | K8: 76230000 | L8: 2026-10-23 | M8: 2026-10-23 | N8: 0 | O8: 0-1 days | P8: HIGH | Q8: UNBOOKED_CORPORATE_ACTION | R8: Custodian processed a corporate action that the books have not captured. | S8: Check the corporate action announcement and entitlement, then book the event. | U8: OPEN
A9: BRK-0008 | B9: STOCK | C9: ACC-1003 | D9: ACC-1003|INE101S01019 | E9: INE101S01019 Aravali Power Ltd | F9: INR | G9: MISSING_AT_CUSTODIAN | H9: 40850 | J9: -40850 | K9: -16850625 | L9: 2026-10-23 | M9: 2026-10-23 | N9: 0 | O9: 0-1 days | P9: HIGH | Q9: POSITION_NOT_AT_CUSTODIAN | R9: Books show a holding the custodian does not hold. | S9: Check whether the purchase settled and whether the securities were delivered to the right account. | U9: OPEN
A10: BRK-0009 | B10: CASH | C10: ACC-1004 | D10: CSH471507 | E10: CORPORATE_ACTION_CASH | F10: USD | G10: MISSING_IN_BOOKS | I10: 69282.71 | J10: 69282.71 | K10: 5819747.6 | M10: 2026-10-21 | N10: 2 | O10: 2-3 days | P10: HIGH | Q10: UNBOOKED_CORPORATE_ACTION | R10: Custodian processed a corporate action that the books have not captured. | S10: Check the corporate action announcement and entitlement, then book the event. | U10: OPEN
A11: BRK-0010 | B11: CASH | C11: ACC-1003 | D11: CSH156802 | E11: TRADE_SETTLEMENT | F11: INR | G11: MISSING_AT_CUSTODIAN | H11: -4422543.8 | J11: -4422543.8 | K11: -4422543.8 | L11: 2026-10-22 | N11: 1 | O11: 0-1 days | P11: HIGH | Q11: POSSIBLE_FAILED_SETTLEMENT | R11: Trade settlement is in the books but no cash moved at the custodian. The trade may have failed or is pending. | S11: Check settlement status with the custodian / counterparty; if failed, update books and inform the client. | U11: OPEN
A12: BRK-0011 | B12: CASH | C12: ACC-1004 | D12: CSH198907 | E12: TRADE_SETTLEMENT | F12: INR | G12: DUPLICATE_AT_CUSTODIAN | H12: 2888328.4 | I12: 5776656.8 | J12: 2888328.4 | K12: 2888328.4 | L12: 2026-10-23 | M12: 2026-10-23 | N12: 0 | O12: 0-1 days | P12: HIGH | Q12: CUSTODIAN_DUPLICATE | R12: The custodian statement shows the same movement twice. | S12: Raise a query with the custodian to reverse the duplicate movement. | U12: OPEN
A13: BRK-0012 | B13: CASH | C13: ACC-1004 | D13: CSH300896 | E13: TRADE_SETTLEMENT | F13: INR | G13: TIMING_DIFF | H13: 2162481.8 | I13: 2162481.8 | J13: 2162481.8 | K13: 2162481.8 | L13: 2026-10-16 | M13: 2026-10-19 | N13: 7 | O13: 4-7 days | P13: HIGH | Q13: SETTLEMENT_LAG | R13: Same transaction, custodian value date is later than books. Usually a settlement delay. | S13: Confirm the actual settlement date with the custodian; expected to auto-clear. Escalate if it stays open past T+3. | U13: OPEN
A14: BRK-0013 | B14: CASH | C14: ACC-1001 | D14: CSH299448 | E14: TRADE_SETTLEMENT | F14: INR | G14: TIMING_DIFF | H14: -2098377.2 | I14: -2098377.2 | J14: -2098377.2 | K14: -2098377.2 | L14: 2026-10-18 | M14: 2026-10-20 | N14: 5 | O14: 4-7 days | P14: HIGH | Q14: SETTLEMENT_LAG | R14: Same transaction, custodian value date is later than books. Usually a settlement delay. | S14: Confirm the actual settlement date with the custodian; expected to auto-clear. Escalate if it stays open past T+3. | U14: OPEN
A15: BRK-0014 | B15: CASH | C15: ACC-1001 | D15: CSH570405 | E15: TRADE_SETTLEMENT | F15: INR | G15: TIMING_DIFF | H15: 1935476.8 | I15: 1935476.8 | J15: 1935476.8 | K15: 1935476.8 | L15: 2026-10-18 | M15: 2026-10-21 | N15: 5 | O15: 4-7 days | P15: HIGH | Q15: SETTLEMENT_LAG | R15: Same transaction, custodian value date is later than books. Usually a settlement delay. | S15: Confirm the actual settlement date with the custodian; expected to auto-clear. Escalate if it stays open past T+3. | U15: OPEN
A16: BRK-0015 | B16: STOCK | C16: ACC-1003 | D16: ACC-1003|INE107S01017 | E16: INE107S01017 Satpura Telecom Ltd | F16: INR | G16: MISSING_IN_BOOKS | I16: 19750 | J16: 19750 | K16: 1901925 | L16: 2026-10-23 | M16: 2026-10-23 | N16: 0 | O16: 0-1 days | P16: HIGH | Q16: UNBOOKED_POSITION | R16: Custodian holds a position that is not in the books. | S16: Find the trade or transfer behind it and book it, or ask the custodian to correct the account. | U16: OPEN
A17: BRK-0016 | B17: CASH | C17: ACC-1001 | D17: CSH939482 | E17: TRADE_SETTLEMENT | F17: INR | G17: TIMING_DIFF | H17: 1800310.5 | I17: 1800310.5 | J17: 1800310.5 | K17: 1800310.5 | L17: 2026-10-17 | M17: 2026-10-20 | N17: 6 | O17: 4-7 days | P17: HIGH | Q17: SETTLEMENT_LAG | R17: Same transaction, custodian value date is later than books. Usually a settlement delay. | S17: Confirm the actual settlement date with the custodian; expected to auto-clear. Escalate if it stays open past T+3. | U17: OPEN
A18: BRK-0017 | B18: CASH | C18: ACC-1004 | D18: CSH589710 | E18: TRADE_SETTLEMENT | F18: INR | G18: MISSING_AT_CUSTODIAN | H18: 1402175.9 | J18: 1402175.9 | K18: 1402175.9 | L18: 2026-10-16 | N18: 7 | O18: 4-7 days | P18: HIGH | Q18: POSSIBLE_FAILED_SETTLEMENT | R18: Trade settlement is in the books but no cash moved at the custodian. The trade may have failed or is pending. | S18: Check settlement status with the custodian / counterparty; if failed, update books and inform the client. | U18: OPEN
A19: BRK-0018 | B19: CASH | C19: ACC-1005 | D19: CSH522179 | E19: TRADE_SETTLEMENT | F19: USD | G19: AMOUNT_DIFF | H19: 2891795 | I19: 2877231.6 | J19: -14563.39 | K19: -1223324.8 | L19: 2026-10-21 | M19: 2026-10-21 | N19: 2 | O19: 2-3 days | P19: HIGH | Q19: CHARGES_DIFF | R19: Small shortfall on a trade settlement, consistent with brokerage, stamp duty or exchange charges not booked. | S19: Get the contract note / charges breakdown and book the charges, or raise a claim if they look wrong. | U19: OPEN
A20: BRK-0019 | B20: CASH | C20: ACC-1005 | D20: CSH662336 | E20: TRADE_SETTLEMENT | F20: INR | G20: TIMING_DIFF | H20: 540933.39 | I20: 540933.39 | J20: 540933.39 | K20: 540933.39 | L20: 2026-10-17 | M20: 2026-10-20 | N20: 6 | O20: 4-7 days | P20: HIGH | Q20: SETTLEMENT_LAG | R20: Same transaction, custodian value date is later than books. Usually a settlement delay. | S20: Confirm the actual settlement date with the custodian; expected to auto-clear. Escalate if it stays open past T+3. | U20: OPEN
A21: BRK-0020 | B21: CASH | C21: ACC-1003 | D21: CSH360735 | E21: TRADE_SETTLEMENT | F21: INR | G21: TIMING_DIFF | H21: 382309.88 | I21: 382309.88 | J21: 382309.88 | K21: 382309.88 | L21: 2026-10-17 | M21: 2026-10-18 | N21: 6 | O21: 4-7 days | P21: HIGH | Q21: SETTLEMENT_LAG | R21: Same transaction, custodian value date is later than books. Usually a settlement delay. | S21: Confirm the actual settlement date with the custodian; expected to auto-clear. Escalate if it stays open past T+3. | U21: OPEN
A22: BRK-0021 | B22: CASH | C22: ACC-1005 | D22: CSH544154 | E22: FEE | F22: INR | G22: MISSING_IN_BOOKS | I22: -6514.18 | J22: -6514.18 | K22: -6514.18 | M22: 2026-10-16 | N22: 7 | O22: 4-7 days | P22: HIGH | Q22: UNBOOKED_CUSTODY_FEE | R22: Custodian debited a fee that is not in the books. | S22: Validate the fee against the fee schedule, then book it or dispute it. | U22: OPEN
A23: BRK-0022 | B23: CASH | C23: ACC-1001 | D23: CSH785197 | E23: DIVIDEND | F23: INR | G23: MISSING_AT_CUSTODIAN | H23: 486046.11 | J23: 486046.11 | K23: 486046.11 | L23: 2026-10-22 | N23: 1 | O23: 0-1 days | P23: MEDIUM | Q23: INCOME_NOT_RECEIVED | R23: Expected income (dividend / coupon) is booked but not yet received at the custodian. | S23: Check the event (record date, pay date, entitlement) and chase the custodian / paying agent for the payment. | U23: OPEN
A24: BRK-0023 | B24: CASH | C24: ACC-1003 | D24: CSH201639 | E24: COUPON | F24: INR | G24: DUPLICATE_IN_BOOKS | H24: 744620.92 | I24: 372310.46 | J24: 372310.46 | K24: 372310.46 | L24: 2026-10-23 | M24: 2026-10-23 | N24: 0 | O24: 0-1 days | P24: MEDIUM | Q24: DOUBLE_BOOKING | R24: The same reference is booked more than once internally. | S24: Reverse the duplicate entry and check why the booking ran twice. | U24: OPEN
A25: BRK-0024 | B25: CASH | C25: ACC-1002 | D25: CSH790993 | E25: DIVIDEND | F25: INR | G25: DUPLICATE_IN_BOOKS | H25: 706634.56 | I25: 353317.28 | J25: 353317.28 | K25: 353317.28 | L25: 2026-10-21 | M25: 2026-10-21 | N25: 2 | O25: 2-3 days | P25: MEDIUM | Q25: DOUBLE_BOOKING | R25: The same reference is booked more than once internally. | S25: Reverse the duplicate entry and check why the booking ran twice. | U25: OPEN
A26: BRK-0025 | B26: STOCK | C26: ACC-1004 | D26: ACC-1004|US9Z02S10015 | E26: US9Z02S10015 Summit Health Corp | F26: USD | G26: QTY_BREAK | H26: 28100 | I26: 28047 | J26: -53 | K26: -333454.8 | L26: 2026-10-23 | M26: 2026-10-23 | N26: 0 | O26: 0-1 days | P26: MEDIUM | Q26: QUANTITY_MISMATCH | R26: Share quantity in the books differs from the custodian. | S26: Check recent trades and pending deliveries for this ISIN; correct the side that is wrong. | U26: OPEN
A27: BRK-0026 | B27: CASH | C27: ACC-1005 | D27: CSH806073 | E27: COUPON | F27: INR | G27: MISSING_AT_CUSTODIAN | H27: 229554.67 | J27: 229554.67 | K27: 229554.67 | L27: 2026-10-23 | N27: 0 | O27: 0-1 days | P27: MEDIUM | Q27: INCOME_NOT_RECEIVED | R27: Expected income (dividend / coupon) is booked but not yet received at the custodian. | S27: Check the event (record date, pay date, entitlement) and chase the custodian / paying agent for the payment. | U27: OPEN
A28: BRK-0027 | B28: CASH | C28: ACC-1005 | D28: CSH163556 | E28: TRADE_SETTLEMENT | F28: INR | G28: AMOUNT_DIFF | H28: -3064524.8 | I28: -3077669.1 | J28: -13144.23 | K28: -13144.23 | L28: 2026-10-19 | M28: 2026-10-19 | N28: 4 | O28: 4-7 days | P28: MEDIUM | Q28: CHARGES_DIFF | R28: Small shortfall on a trade settlement, consistent with brokerage, stamp duty or exchange charges not booked. | S28: Get the contract note / charges breakdown and book the charges, or raise a claim if they look wrong. | U28: OPEN
A29: BRK-0028 | B29: CASH | C29: ACC-1002 | D29: CSH551989 | E29: TRADE_SETTLEMENT | F29: INR | G29: MISSING_IN_BOOKS | I29: -88263.04 | J29: -88263.04 | K29: -88263.04 | M29: 2026-10-22 | N29: 1 | O29: 0-1 days | P29: LOW | Q29: UNBOOKED_TRANSACTION | R29: Cash moved at the custodian with no matching entry in the books. | S29: Identify the instruction behind the movement; book it if valid, otherwise query the custodian. | U29: OPEN
A30: BRK-0029 | B30: STOCK | C30: ACC-1001 | D30: ACC-1001|INE105S01011 | E30: INE105S01011 Vindhya Cement Ltd | F30: INR | G30: QTY_BREAK | H30: 16100 | I30: 16002 | J30: -98 | K30: -84843.5 | L30: 2026-10-23 | M30: 2026-10-23 | N30: 0 | O30: 0-1 days | P30: LOW | Q30: QUANTITY_MISMATCH | R30: Share quantity in the books differs from the custodian. | S30: Check recent trades and pending deliveries for this ISIN; correct the side that is wrong. | U30: OPEN
A31: BRK-0030 | B31: CASH | C31: ACC-1002 | D31: CSH863587 | E31: DIVIDEND | F31: INR | G31: AMOUNT_DIFF | H31: 116001.21 | I31: 92800.97 | J31: -23200.24 | K31: -23200.24 | L31: 2026-10-22 | M31: 2026-10-22 | N31: 1 | O31: 0-1 days | P31: LOW | Q31: WITHHOLDING_TAX | R31: Income received net of tax; books carry the gross amount. | S31: Book the withholding tax entry and check the applied tax rate against the client's tax status / treaty rate. | U31: OPEN
A32: BRK-0031 | B32: CASH | C32: ACC-1001 | D32: CSH455784 | E32: DIVIDEND | F32: INR | G32: AMOUNT_DIFF | H32: 179064.86 | I32: 161158.37 | J32: -17906.49 | K32: -17906.49 | L32: 2026-10-21 | M32: 2026-10-21 | N32: 2 | O32: 2-3 days | P32: LOW | Q32: WITHHOLDING_TAX | R32: Income received net of tax; books carry the gross amount. | S32: Book the withholding tax entry and check the applied tax rate against the client's tax status / treaty rate. | U32: OPEN
A33: BRK-0032 | B33: STOCK | C33: ACC-1001 | D33: ACC-1001|INE106S01019 | E33: INE106S01019 Godavari Foods Ltd | F33: INR | G33: QTY_BREAK | H33: 37700 | I33: 37745 | J33: 45 | K33: 15394.5 | L33: 2026-10-23 | M33: 2026-10-23 | N33: 0 | O33: 0-1 days | P33: LOW | Q33: QUANTITY_MISMATCH | R33: Share quantity in the books differs from the custodian. | S33: Check recent trades and pending deliveries for this ISIN; correct the side that is wrong. | U33: OPEN
A34: BRK-0033 | B34: CASH | C34: ACC-1003 | D34: CSH777568 | E34: FX_CONVERSION | F34: INR | G34: AMOUNT_DIFF | H34: -2622601.9 | I34: -2610532.4 | J34: 12069.41 | K34: 12069.41 | L34: 2026-10-23 | M34: 2026-10-23 | N34: 0 | O34: 0-1 days | P34: LOW | Q34: FX_RATE_DIFF | R34: FX conversion settled at a different rate than the one booked. | S34: Compare the booked rate with the custodian's FX confirmation and book the rate difference. | U34: OPEN
A35: BRK-0034 | B35: CASH | C35: ACC-1001 | D35: CSH531071 | E35: FEE | F35: INR | G35: MISSING_IN_BOOKS | I35: -6023.31 | J35: -6023.31 | K35: -6023.31 | M35: 2026-10-21 | N35: 2 | O35: 2-3 days | P35: LOW | Q35: UNBOOKED_CUSTODY_FEE | R35: Custodian debited a fee that is not in the books. | S35: Validate the fee against the fee schedule, then book it or dispute it. | U35: OPEN
A36: BRK-0035 | B36: CASH | C36: ACC-1003 | D36: CSH203198 | E36: FX_CONVERSION | F36: INR | G36: AMOUNT_DIFF | H36: -892484.13 | I36: -889426.89 | J36: 3057.24 | K36: 3057.24 | L36: 2026-10-23 | M36: 2026-10-23 | N36: 0 | O36: 0-1 days | P36: LOW | Q36: FX_RATE_DIFF | R36: FX conversion settled at a different rate than the one booked. | S36: Compare the booked rate with the custodian's FX confirmation and book the rate difference. | U36: OPEN

Sheet Aging
A1: Break aging (cash + stock)
A3: Age bucket | B3: HIGH | C3: MEDIUM | D3: LOW | E3: Total | F3: Value (INR eq.)
A4: 0-1 days | B4: =COUNTIFS(Breaks!$O$2:$O$36,$A4,Breaks!$P$2:$P$36,"HIGH") -> 8 | C4: =COUNTIFS(Breaks!$O$2:$O$36,$A4,Breaks!$P$2:$P$36,"MEDIUM") -> 4 | D4: =COUNTIFS(Breaks!$O$2:$O$36,$A4,Breaks!$P$2:$P$36,"LOW") -> 6 | E4: =SUM(B4:D4) -> 18 | F4: =SUMPRODUCT((Breaks!$O$2:$O$36=$A4)*ABS(Breaks!$K$2:$K$36)) -> 6.1275356e+08
A5: 2-3 days | B5: =COUNTIFS(Breaks!$O$2:$O$36,$A5,Breaks!$P$2:$P$36,"HIGH") -> 3 | C5: =COUNTIFS(Breaks!$O$2:$O$36,$A5,Breaks!$P$2:$P$36,"MEDIUM") -> 1 | D5: =COUNTIFS(Breaks!$O$2:$O$36,$A5,Breaks!$P$2:$P$36,"LOW") -> 2 | E5: =SUM(B5:D5) -> 6 | F5: =SUMPRODUCT((Breaks!$O$2:$O$36=$A5)*ABS(Breaks!$K$2:$K$36)) -> 1.2476068e+08
A6: 4-7 days | B6: =COUNTIFS(Breaks!$O$2:$O$36,$A6,Breaks!$P$2:$P$36,"HIGH") -> 10 | C6: =COUNTIFS(Breaks!$O$2:$O$36,$A6,Breaks!$P$2:$P$36,"MEDIUM") -> 1 | D6: =COUNTIFS(Breaks!$O$2:$O$36,$A6,Breaks!$P$2:$P$36,"LOW") -> 0 | E6: =SUM(B6:D6) -> 11 | F6: =SUMPRODUCT((Breaks!$O$2:$O$36=$A6)*ABS(Breaks!$K$2:$K$36)) -> 4.9020949e+08
A7: 8+ days | B7: =COUNTIFS(Breaks!$O$2:$O$36,$A7,Breaks!$P$2:$P$36,"HIGH") -> 0 | C7: =COUNTIFS(Breaks!$O$2:$O$36,$A7,Breaks!$P$2:$P$36,"MEDIUM") -> 0 | D7: =COUNTIFS(Breaks!$O$2:$O$36,$A7,Breaks!$P$2:$P$36,"LOW") -> 0 | E7: =SUM(B7:D7) -> 0 | F7: =SUMPRODUCT((Breaks!$O$2:$O$36=$A7)*ABS(Breaks!$K$2:$K$36)) -> 0
A8: Total | B8: =SUM(B4:B7) -> 21 | C8: =SUM(C4:C7) -> 6 | D8: =SUM(D4:D7) -> 8 | E8: =SUM(E4:E7) -> 35 | F8: =SUM(F4:F7) -> 1.2277237e+09
A10: Stock breaks are dated the business date (age 0); cash breaks are aged from the books value date (or custodian date if missing in books).

Sheet Cash Recon
A1: Recon | B1: Account | C1: Reference / Position | D1: Txn Type / Security | E1: Ccy | F1: Books | G1: Custodian | H1: Status | I1: Difference | J1: Books Date | K1: Custodian Date
A2: CASH | B2: ACC-1002 | C2: CSH102260 | D2: FEE | E2: USD | F2: -12735.43 | G2: -12735.43 | H2: MATCHED | I2: 0 | J2: 2026-10-03 | K2: 2026-10-03
A3: CASH | B3: ACC-1004 | C3: CSH103717 | D3: TRADE_SETTLEMENT | E3: INR | F3: -1370688.3 | G3: -1370688.3 | H3: MATCHED | I3: 0 | J3: 2026-10-02 | K3: 2026-10-02
A4: CASH | B4: ACC-1005 | C4: CSH108203 | D4: FEE | E4: INR | F4: -10020.47 | G4: -10020.47 | H4: MATCHED | I4: 0 | J4: 2026-10-04 | K4: 2026-10-04
A5: CASH | B5: ACC-1002 | C5: CSH109767 | D5: COUPON | E5: INR | F5: 206181.92 | G5: 206181.92 | H5: MATCHED | I5: 0 | J5: 2026-10-21 | K5: 2026-10-21
A6: CASH | B6: ACC-1005 | C6: CSH115474 | D6: TRADE_SETTLEMENT | E6: INR | F6: -4432798.2 | G6: -4432798.2 | H6: MATCHED | I6: 0 | J6: 2026-10-10 | K6: 2026-10-10
A7: CASH | B7: ACC-1001 | C7: CSH141672 | D7: TRADE_SETTLEMENT | E7: USD | F7: 2995468 | G7: 2995468 | H7: MATCHED | I7: 0 | J7: 2026-10-22 | K7: 2026-10-22
A8: CASH | B8: ACC-1001 | C8: CSH146228 | D8: FX_CONVERSION | E8: INR | F8: -2589920.4 | G8: -2589920.4 | H8: MATCHED | I8: 0 | J8: 2026-10-11 | K8: 2026-10-11
A9: CASH | B9: ACC-1003 | C9: CSH152578 | D9: TRADE_SETTLEMENT | E9: INR | F9: 4333039.9 | G9: 4333039.9 | H9: MATCHED | I9: 0 | J9: 2026-10-05 | K9: 2026-10-05
A10: CASH | B10: ACC-1003 | C10: CSH153045 | D10: FEE | E10: INR | F10: -4201.27 | G10: -4201.27 | H10: MATCHED | I10: 0 | J10: 2026-10-22 | K10: 2026-10-22
A11: CASH | B11: ACC-1004 | C11: CSH153266 | D11: COUPON | E11: INR | F11: 160270.27 | G11: 160270.27 | H11: MATCHED | I11: 0 | J11: 2026-10-12 | K11: 2026-10-12
A12: CASH | B12: ACC-1003 | C12: CSH156802 | D12: TRADE_SETTLEMENT | E12: INR | F12: -4422543.8 | H12: MISSING_AT_CUSTODIAN | I12: -4422543.8 | J12: 2026-10-22
A13: CASH | B13: ACC-1001 | C13: CSH159642 | D13: DIVIDEND | E13: INR | F13: 306391.48 | G13: 306391.48 | H13: MATCHED | I13: 0 | J13: 2026-10-23 | K13: 2026-10-23
A14: CASH | B14: ACC-1005 | C14: CSH159942 | D14: DIVIDEND | E14: INR | F14: 278199.12 | G14: 278199.12 | H14: MATCHED | I14: 0 | J14: 2026-10-08 | K14: 2026-10-08
A15: CASH | B15: ACC-1004 | C15: CSH161324 | D15: TRADE_SETTLEMENT | E15: INR | F15: -2373978.5 | G15: -2373978.5 | H15: MATCHED | I15: 0 | J15: 2026-10-03 | K15: 2026-10-03
A16: CASH | B16: ACC-1005 | C16: CSH161483 | D16: FX_CONVERSION | E16: INR | F16: 2508370.6 | G16: 2508370.6 | H16: MATCHED | I16: 0 | J16: 2026-10-12 | K16: 2026-10-12
A17: CASH | B17: ACC-1005 | C17: CSH163556 | D17: TRADE_SETTLEMENT | E17: INR | F17: -3064524.8 | G17: -3077669.1 | H17: AMOUNT_DIFF | I17: -13144.23 | J17: 2026-10-19 | K17: 2026-10-19
A18: CASH | B18: ACC-1001 | C18: CSH163918 | D18: DIVIDEND | E18: INR | F18: 354087.8 | G18: 354087.8 | H18: MATCHED | I18: 0 | J18: 2026-10-13 | K18: 2026-10-13
A19: CASH | B19: ACC-1003 | C19: CSH171262 | D19: DIVIDEND | E19: INR | F19: 336716.09 | G19: 336716.09 | H19: MATCHED | I19: 0 | J19: 2026-10-10 | K19: 2026-10-10
A20: CASH | B20: ACC-1004 | C20: CSH171849 | D20: TRADE_SETTLEMENT | E20: USD | F20: -1606859.9 | G20: -1606859.9 | H20: MATCHED | I20: 0 | J20: 2026-10-06 | K20: 2026-10-06
A21: CASH | B21: ACC-1004 | C21: CSH172132 | D21: DIVIDEND | E21: USD | F21: 298088.44 | G21: 298088.44 | H21: MATCHED | I21: 0 | J21: 2026-10-01 | K21: 2026-10-01
A22: CASH | B22: ACC-1002 | C22: CSH176066 | D22: COUPON | E22: INR | F22: 357361.99 | G22: 357361.99 | H22: MATCHED | I22: 0 | J22: 2026-10-01 | K22: 2026-10-01
A23: CASH | B23: ACC-1004 | C23: CSH176819 | D23: DIVIDEND | E23: INR | F23: 298274.94 | G23: 298274.94 | H23: MATCHED | I23: 0 | J23: 2026-10-10 | K23: 2026-10-10
A24: CASH | B24: ACC-1001 | C24: CSH179046 | D24: FX_CONVERSION | E24: INR | F24: -1138902.6 | G24: -1138902.6 | H24: MATCHED | I24: 0 | J24: 2026-10-19 | K24: 2026-10-19
... A94: CASH | B94: ACC-1002 | C94: CSH465962 | D94: FX_CONVERSION | E94: INR | F94: 2565850.4 | G94: 2565850.4 | H94: MATCHED | I94: 0 | J94: 2026-10-20 | K94: 2026-10-20
A95: CASH | B95: ACC-1004 | C95: CSH471507 | D95: CORPORATE_ACTION_CASH | E95: USD | G95: 69282.71 | H95: MISSING_IN_BOOKS | I95: 69282.71 | K95: 2026-10-21
A96: CASH | B96: ACC-1003 | C96: CSH487477 | D96: TRADE_SETTLEMENT | E96: INR | F96: -3900069.8 | G96: -3900069.8 | H96: MATCHED | I96: 0 | J96: 2026-10-18 | K96: 2026-10-18
A97: CASH | B97: ACC-1003 | C97: CSH497382 | D97: TRADE_SETTLEMENT | E97: USD | F97: 3675180.9 | G97: 3675180.9 | H97: MATCHED | I97: 0 | J97: 2026-10-09 | K97: 2026-10-09
A98: CASH | B98: ACC-1003 | C98: CSH509386 | D98: COUPON | E98: INR | F98: 384898.03 | G98: 384898.03 | H98: MATCHED | I98: 0 | J98: 2026-10-02 | K98: 2026-10-02
A99: CASH | B99: ACC-1001 | C99: CSH515011 | D99: TRADE_SETTLEMENT | E99: INR | F99: 275302.72 | G99: 275302.72 | H99: MATCHED | I99: 0 | J99: 2026-10-01 | K99: 2026-10-01
A100: CASH | B100: ACC-1004 | C100: CSH520521 | D100: TRADE_SETTLEMENT | E100: INR | F100: 4030951.1 | G100: 4030951.1 | H100: MATCHED | I100: 0 | J100: 2026-10-14 | K100: 2026-10-14
A101: CASH | B101: ACC-1005 | C101: CSH522179 | D101: TRADE_SETTLEMENT | E101: USD | F101: 2891795 | G101: 2877231.6 | H101: AMOUNT_DIFF | I101: -14563.39 | J101: 2026-10-21 | K101: 2026-10-21
A102: CASH | B102: ACC-1003 | C102: CSH523389 | D102: FEE | E102: USD | F102: -15247.24 | G102: -15247.24 | H102: MATCHED | I102: 0 | J102: 2026-10-05 | K102: 2026-10-05
A103: CASH | B103: ACC-1003 | C103: CSH526156 | D103: FEE | E103: INR | F103: -12951.71 | G103: -12951.71 | H103: MATCHED | I103: 0 | J103: 2026-10-05 | K103: 2026-10-05
A104: CASH | B104: ACC-1001 | C104: CSH531071 | D104: FEE | E104: INR | G104: -6023.31 | H104: MISSING_IN_BOOKS | I104: -6023.31 | K104: 2026-10-21
A105: CASH | B105: ACC-1003 | C105: CSH539589 | D105: TRADE_SETTLEMENT | E105: INR | F105: 402339.81 | G105: 402339.81 | H105: MATCHED | I105: 0 | J105: 2026-10-01 | K105: 2026-10-01
A106: CASH | B106: ACC-1001 | C106: CSH542374 | D106: TRADE_SETTLEMENT | E106: INR | F106: 3446182.6 | G106: 3446182.6 | H106: MATCHED_WITHIN_TOLERANCE | I106: 0.01 | J106: 2026-10-22 | K106: 2026-10-22
A107: CASH | B107: ACC-1005 | C107: CSH543555 | D107: TRADE_SETTLEMENT | E107: INR | F107: 3467051.9 | G107: 3467051.9 | H107: MATCHED | I107: 0 | J107: 2026-10-14 | K107: 2026-10-14
A108: CASH | B108: ACC-1003 | C108: CSH544151 | D108: FX_CONVERSION | E108: INR | F108: 2070602.5 | G108: 2070602.5 | H108: MATCHED | I108: 0 | J108: 2026-10-12 | K108: 2026-10-12
A109: CASH | B109: ACC-1005 | C109: CSH544154 | D109: FEE | E109: INR | G109: -6514.18 | H109: MISSING_IN_BOOKS | I109: -6514.18 | K109: 2026-10-16
...

Sheet Stock Recon
A1: Recon | B1: Account | C1: Reference / Position | D1: Txn Type / Security | E1: Ccy | F1: Books | G1: Custodian | H1: Status | I1: Difference | J1: Books Date | K1: Custodian Date
A2: STOCK | B2: ACC-1001 | C2: ACC-1001|INE102S01017 | D2: INE102S01017 Deccan Steel Ltd | E2: INR | F2: 6250 | G2: 6250 | H2: MATCHED | I2: 0 | J2: 2026-10-23 | K2: 2026-10-23
A3: STOCK | B3: ACC-1001 | C3: ACC-1001|INE103S01015 | D3: INE103S01015 Konkan Ports Ltd | E3: INR | F3: 31850 | G3: 31850 | H3: MATCHED | I3: 0 | J3: 2026-10-23 | K3: 2026-10-23
A4: STOCK | B4: ACC-1001 | C4: ACC-1001|INE105S01011 | D4: INE105S01011 Vindhya Cement Ltd | E4: INR | F4: 16100 | G4: 16002 | H4: QTY_BREAK | I4: -98 | J4: 2026-10-23 | K4: 2026-10-23
A5: STOCK | B5: ACC-1001 | C5: ACC-1001|INE106S01019 | D5: INE106S01019 Godavari Foods Ltd | E5: INR | F5: 37700 | G5: 37745 | H5: QTY_BREAK | I5: 45 | J5: 2026-10-23 | K5: 2026-10-23
A6: STOCK | B6: ACC-1001 | C6: ACC-1001|INE107S01017 | D6: INE107S01017 Satpura Telecom Ltd | E6: INR | F6: 5050 | G6: 5050 | H6: MATCHED | I6: 0 | J6: 2026-10-23 | K6: 2026-10-23
A7: STOCK | B7: ACC-1001 | C7: ACC-1001|INE108S01015 | D7: INE108S01015 Kaveri Finance Ltd | E7: INR | F7: 23800 | G7: 23800 | H7: MATCHED | I7: 0 | J7: 2026-10-23 | K7: 2026-10-23
A8: STOCK | B8: ACC-1001 | C8: ACC-1001|US9Z01S10017 | D8: US9Z01S10017 Harbor Tech Inc | E8: USD | F8: 16650 | H8: MISSING_AT_CUSTODIAN | I8: -16650 | J8: 2026-10-23 | K8: 2026-10-23
A9: STOCK | B9: ACC-1001 | C9: ACC-1001|US9Z02S10015 | D9: US9Z02S10015 Summit Health Corp | E9: USD | F9: 34800 | G9: 34800 | H9: MATCHED | I9: 0 | J9: 2026-10-23 | K9: 2026-10-23
A10: STOCK | B10: ACC-1001 | C10: ACC-1001|US9Z03S10013 | D10: US9Z03S10013 Pioneer Energy Inc | E10: USD | F10: 17750 | G10: 17750 | H10: MATCHED | I10: 0 | J10: 2026-10-23 | K10: 2026-10-23
A11: STOCK | B11: ACC-1002 | C11: ACC-1002|INE101S01019 | D11: INE101S01019 Aravali Power Ltd | E11: INR | F11: 35350 | G11: 35350 | H11: MATCHED | I11: 0 | J11: 2026-10-23 | K11: 2026-10-23
A12: STOCK | B12: ACC-1002 | C12: ACC-1002|INE102S01017 | D12: INE102S01017 Deccan Steel Ltd | E12: INR | F12: 19600 | G12: 19600 | H12: MATCHED | I12: 0 | J12: 2026-10-23 | K12: 2026-10-23
A13: STOCK | B13: ACC-1002 | C13: ACC-1002|INE103S01015 | D13: INE103S01015 Konkan Ports Ltd | E13: INR | F13: 41500 | G13: 41500 | H13: MATCHED | I13: 0 | J13: 2026-10-23 | K13: 2026-10-23
A14: STOCK | B14: ACC-1002 | C14: ACC-1002|INE104S01013 | D14: INE104S01013 Narmada Pharma Ltd | E14: INR | F14: 4800 | G14: 4800 | H14: MATCHED | I14: 0 | J14: 2026-10-23 | K14: 2026-10-23
A15: STOCK | B15: ACC-1002 | C15: ACC-1002|INE106S01019 | D15: INE106S01019 Godavari Foods Ltd | E15: INR | F15: 3900 | G15: 3900 | H15: MATCHED | I15: 0 | J15: 2026-10-23 | K15: 2026-10-23
A16: STOCK | B16: ACC-1002 | C16: ACC-1002|INE107S01017 | D16: INE107S01017 Satpura Telecom Ltd | E16: INR | F16: 33700 | G16: 33700 | H16: MATCHED | I16: 0 | J16: 2026-10-23 | K16: 2026-10-23
A17: STOCK | B17: ACC-1002 | C17: ACC-1002|INE108S01015 | D17: INE108S01015 Kaveri Finance Ltd | E17: INR | F17: 49500 | G17: 99000 | H17: QTY_BREAK | I17: 49500 | J17: 2026-10-23 | K17: 2026-10-23
A18: STOCK | B18: ACC-1002 | C18: ACC-1002|US9Z02S10015 | D18: US9Z02S10015 Summit Health Corp | E18: USD | F18: 33600 | G18: 33600 | H18: MATCHED | I18: 0 | J18: 2026-10-23 | K18: 2026-10-23
A19: STOCK | B19: ACC-1002 | C19: ACC-1002|US9Z03S10013 | D19: US9Z03S10013 Pioneer Energy Inc | E19: USD | F19: 21750 | G19: 21750 | H19: MATCHED | I19: 0 | J19: 2026-10-23 | K19: 2026-10-23
A20: STOCK | B20: ACC-1003 | C20: ACC-1003|INE101S01019 | D20: INE101S01019 Aravali Power Ltd | E20: INR | F20: 40850 | H20: MISSING_AT_CUSTODIAN | I20: -40850 | J20: 2026-10-23 | K20: 2026-10-23
A21: STOCK | B21: ACC-1003 | C21: ACC-1003|INE103S01015 | D21: INE103S01015 Konkan Ports Ltd | E21: INR | F21: 13050 | G21: 13050 | H21: MATCHED | I21: 0 | J21: 2026-10-23 | K21: 2026-10-23
A22: STOCK | B22: ACC-1003 | C22: ACC-1003|INE104S01013 | D22: INE104S01013 Narmada Pharma Ltd | E22: INR | F22: 20600 | G22: 20600 | H22: MATCHED | I22: 0 | J22: 2026-10-23 | K22: 2026-10-23
A23: STOCK | B23: ACC-1003 | C23: ACC-1003|INE105S01011 | D23: INE105S01011 Vindhya Cement Ltd | E23: INR | F23: 19500 | G23: 19500 | H23: MATCHED | I23: 0 | J23: 2026-10-23 | K23: 2026-10-23
A24: STOCK | B24: ACC-1003 | C24: ACC-1003|INE106S01019 | D24: INE106S01019 Godavari Foods Ltd | E24: INR | F24: 30000 | G24: 30000 | H24: MATCHED | I24: 0 | J24: 2026-10-23 | K24: 2026-10-23
A25: STOCK | B25: ACC-1003 | C25: ACC-1003|INE107S01017 | D25: INE107S01017 Satpura Telecom Ltd | E25: INR | G25: 19750 | H25: MISSING_IN_BOOKS | I25: 19750 | J25: 2026-10-23 | K25: 2026-10-23
A26: STOCK | B26: ACC-1003 | C26: ACC-1003|US9Z01S10017 | D26: US9Z01S10017 Harbor Tech Inc | E26: USD | F26: 4400 | G26: 4400 | H26: MATCHED | I26: 0 | J26: 2026-10-23 | K26: 2026-10-23
A27: STOCK | B27: ACC-1003 | C27: ACC-1003|US9Z02S10015 | D27: US9Z02S10015 Summit Health Corp | E27: USD | F27: 34000 | G27: 34000 | H27: MATCHED | I27: 0 | J27: 2026-10-23 | K27: 2026-10-23
A28: STOCK | B28: ACC-1003 | C28: ACC-1003|US9Z03S10013 | D28: US9Z03S10013 Pioneer Energy Inc | E28: USD | F28: 49600 | G28: 49600 | H28: MATCHED | I28: 0 | J28: 2026-10-23 | K28: 2026-10-23
A29: STOCK | B29: ACC-1004 | C29: ACC-1004|INE101S01019 | D29: INE101S01019 Aravali Power Ltd | E29: INR | F29: 8000 | G29: 8000 | H29: MATCHED | I29: 0 | J29: 2026-10-23 | K29: 2026-10-23
A30: STOCK | B30: ACC-1004 | C30: ACC-1004|INE103S01015 | D30: INE103S01015 Konkan Ports Ltd | E30: INR | F30: 19750 | G30: 19750 | H30: MATCHED | I30: 0 | J30: 2026-10-23 | K30: 2026-10-23
A31: STOCK | B31: ACC-1004 | C31: ACC-1004|INE104S01013 | D31: INE104S01013 Narmada Pharma Ltd | E31: INR | F31: 15250 | G31: 15250 | H31: MATCHED | I31: 0 | J31: 2026-10-23 | K31: 2026-10-23
A32: STOCK | B32: ACC-1004 | C32: ACC-1004|INE106S01019 | D32: INE106S01019 Godavari Foods Ltd | E32: INR | F32: 6800 | G32: 6800 | H32: MATCHED | I32: 0 | J32: 2026-10-23 | K32: 2026-10-23
A33: STOCK | B33: ACC-1004 | C33: ACC-1004|INE107S01017 | D33: INE107S01017 Satpura Telecom Ltd | E33: INR | F33: 34250 | G33: 34250 | H33: MATCHED | I33: 0 | J33: 2026-10-23 | K33: 2026-10-23
A34: STOCK | B34: ACC-1004 | C34: ACC-1004|INE108S01015 | D34: INE108S01015 Kaveri Finance Ltd | E34: INR | F34: 21350 | G34: 21350 | H34: MATCHED | I34: 0 | J34: 2026-10-23 | K34: 2026-10-23
A35: STOCK | B35: ACC-1004 | C35: ACC-1004|US9Z01S10017 | D35: US9Z01S10017 Harbor Tech Inc | E35: USD | F35: 17050 | G35: 17050 | H35: MATCHED | I35: 0 | J35: 2026-10-23 | K35: 2026-10-23
A36: STOCK | B36: ACC-1004 | C36: ACC-1004|US9Z02S10015 | D36: US9Z02S10015 Summit Health Corp | E36: USD | F36: 28100 | G36: 28047 | H36: QTY_BREAK | I36: -53 | J36: 2026-10-23 | K36: 2026-10-23
A37: STOCK | B37: ACC-1004 | C37: ACC-1004|US9Z03S10013 | D37: US9Z03S10013 Pioneer Energy Inc | E37: USD | F37: 13750 | G37: 13750 | H37: MATCHED | I37: 0 | J37: 2026-10-23 | K37: 2026-10-23
... A43: STOCK | B43: ACC-1005 | C43: ACC-1005|INE108S01015 | D43: INE108S01015 Kaveri Finance Ltd | E43: INR | F43: 32300 | G43: 32300 | H43: MATCHED | I43: 0 | J43: 2026-10-23 | K43: 2026-10-23
A44: STOCK | B44: ACC-1005 | C44: ACC-1005|US9Z01S10017 | D44: US9Z01S10017 Harbor Tech Inc | E44: USD | G44: 11200 | H44: MISSING_IN_BOOKS | I44: 11200 | J44: 2026-10-23 | K44: 2026-10-23
A45: STOCK | B45: ACC-1005 | C45: ACC-1005|US9Z02S10015 | D45: US9Z02S10015 Summit Health Corp | E45: USD | F45: 26100 | G45: 39150 | H45: QTY_BREAK | I45: 13050 | J45: 2026-10-23 | K45: 2026-10-23
...

Sheet Assumptions
A1: Control rules used in this run (from config.py)
A3: Rule | B3: Value | C3: Why
A4: Cash amount tolerance (absolute) | B4: 0.01 | C4: Absorbs paise/cent rounding only.
A5: Stock quantity tolerance | B5: 0 | C5: Positions reconcile to the exact share.
A6: USD to INR (reporting only) | B6: 84 | C6: Illustrative fixed rate, not market data.
A7: HIGH priority value (INR eq.) | B7: 1000000 | C7: Break value at or above this is HIGH.
A8: MEDIUM priority value (INR eq.) | B8: 100000 | C8: Break value at or above this is at least MEDIUM.
A9: HIGH priority age (days) | B9: 6 | C9: Open this many days or more is HIGH.
A10: MEDIUM priority age (days) | B10: 3 | C10: Open this many days or more is at least MEDIUM.
A11: Corporate action ratios checked | B11: 1.1, 1.2, 1.25, 1.5, 2.0, 3.0, 4.0, 5.0, 10.0 | C11: Custodian qty / books qty equal to one of these suggests an unbooked split or bonus.
